<mujoco model="g1_dex3_tabletop">
  <compiler angle="radian" meshdir="meshes" autolimits="true" />

  <option timestep="0.016667" gravity="0 0 -9.81" cone="pyramidal" solver="Newton"
          iterations="20" tolerance="1e-6" />

  <default>
    <default class="arm_motor">
      <joint damping="0.5" armature="0.01" frictionloss="0.2"/>
      <position kp="100" kv="10" />
    </default>
    <default class="wrist_motor">
      <joint damping="0.3" armature="0.005" frictionloss="0.1"/>
      <position kp="50" kv="5" />
    </default>
    <default class="hand_motor">
      <joint damping="0.1" armature="0.002" frictionloss="0.05"/>
      <position kp="10" kv="1" />
    </default>
    <default class="visual">
      <geom contype="0" conaffinity="0" group="1" density="0" />
    </default>
    <default class="collision_body">
      <geom contype="2" conaffinity="1" group="3" rgba="0.5 0.5 0.5 0.3" />
    </default>
    <default class="collision_arm">
      <geom contype="1" conaffinity="2" group="3" rgba="0.3 0.3 0.8 0.3" />
    </default>
    <default class="collision_hand">
      <geom contype="4" conaffinity="11" group="3" rgba="0.3 0.8 0.3 0.3" />
    </default>
    <default class="collision_object">
      <geom contype="8" conaffinity="15" group="0" />
    </default>
  </default>

  <asset>
    <!-- G1 body meshes -->
    <mesh name="pelvis" file="pelvis.STL" />
    <mesh name="pelvis_contour_link" file="pelvis_contour_link.STL" />
    <mesh name="waist_yaw_link" file="waist_yaw_link.STL" />
    <mesh name="waist_roll_link" file="waist_roll_link.STL" />
    <mesh name="torso_link" file="torso_link.STL" />
    <mesh name="logo_link" file="logo_link.STL" />
    <mesh name="head_link" file="head_link.STL" />
    <mesh name="waist_support_link" file="waist_support_link.STL" />
    <mesh name="left_shoulder_pitch_link" file="left_shoulder_pitch_link.STL" />
    <mesh name="left_shoulder_roll_link" file="left_shoulder_roll_link.STL" />
    <mesh name="left_shoulder_yaw_link" file="left_shoulder_yaw_link.STL" />
    <mesh name="left_elbow_link" file="left_elbow_link.STL" />
    <mesh name="left_wrist_roll_link" file="left_wrist_roll_link.STL" />
    <mesh name="left_wrist_pitch_link" file="left_wrist_pitch_link.STL" />
    <mesh name="left_wrist_yaw_link" file="left_wrist_yaw_link.STL" />
    <mesh name="right_shoulder_pitch_link" file="right_shoulder_pitch_link.STL" />
    <mesh name="right_shoulder_roll_link" file="right_shoulder_roll_link.STL" />
    <mesh name="right_shoulder_yaw_link" file="right_shoulder_yaw_link.STL" />
    <mesh name="right_elbow_link" file="right_elbow_link.STL" />
    <mesh name="right_wrist_roll_link" file="right_wrist_roll_link.STL" />
    <mesh name="right_wrist_pitch_link" file="right_wrist_pitch_link.STL" />
    <mesh name="right_wrist_yaw_link" file="right_wrist_yaw_link.STL" />
    <!-- Leg meshes (visual only, locked) -->
    <mesh name="left_hip_pitch_link" file="left_hip_pitch_link.STL" />
    <mesh name="left_hip_roll_link" file="left_hip_roll_link.STL" />
    <mesh name="left_hip_yaw_link" file="left_hip_yaw_link.STL" />
    <mesh name="left_knee_link" file="left_knee_link.STL" />
    <mesh name="left_ankle_pitch_link" file="left_ankle_pitch_link.STL" />
    <mesh name="left_ankle_roll_link" file="left_ankle_roll_link.STL" />
    <mesh name="right_hip_pitch_link" file="right_hip_pitch_link.STL" />
    <mesh name="right_hip_roll_link" file="right_hip_roll_link.STL" />
    <mesh name="right_hip_yaw_link" file="right_hip_yaw_link.STL" />
    <mesh name="right_knee_link" file="right_knee_link.STL" />
    <mesh name="right_ankle_pitch_link" file="right_ankle_pitch_link.STL" />
    <mesh name="right_ankle_roll_link" file="right_ankle_roll_link.STL" />
    <!-- Dex3 hand meshes -->
    <mesh name="left_hand_palm_link" file="left_hand_palm_link.STL" />
    <mesh name="left_hand_thumb_0_link" file="left_hand_thumb_0_link.STL" />
    <mesh name="left_hand_thumb_1_link" file="left_hand_thumb_1_link.STL" />
    <mesh name="left_hand_thumb_2_link" file="left_hand_thumb_2_link.STL" />
    <mesh name="left_hand_middle_0_link" file="left_hand_middle_0_link.STL" />
    <mesh name="left_hand_middle_1_link" file="left_hand_middle_1_link.STL" />
    <mesh name="left_hand_index_0_link" file="left_hand_index_0_link.STL" />
    <mesh name="left_hand_index_1_link" file="left_hand_index_1_link.STL" />
    <mesh name="right_hand_palm_link" file="right_hand_palm_link.STL" />
    <mesh name="right_hand_thumb_0_link" file="right_hand_thumb_0_link.STL" />
    <mesh name="right_hand_thumb_1_link" file="right_hand_thumb_1_link.STL" />
    <mesh name="right_hand_thumb_2_link" file="right_hand_thumb_2_link.STL" />
    <mesh name="right_hand_middle_0_link" file="right_hand_middle_0_link.STL" />
    <mesh name="right_hand_middle_1_link" file="right_hand_middle_1_link.STL" />
    <mesh name="right_hand_index_0_link" file="right_hand_index_0_link.STL" />
    <mesh name="right_hand_index_1_link" file="right_hand_index_1_link.STL" />
    <!-- Table material -->
    <material name="table_wood" rgba="0.55 0.41 0.08 1" />
    <material name="red_obj" rgba="0.8 0.2 0.2 1" />
    <material name="blue_obj" rgba="0.2 0.2 0.8 1" />
    <material name="green_obj" rgba="0.2 0.7 0.35 1" />
  </asset>

  <worldbody>
    <!-- Ground plane -->
    <geom name="floor" type="plane" size="5 5 0.05" rgba="0.23 0.29 0.35 1"
          contype="16" conaffinity="31" />
    <light pos="0 0 3" dir="0 0 -1" directional="true" diffuse="0.8 0.8 0.8" />
    <light pos="2 2 3" dir="-0.5 -0.5 -1" diffuse="0.4 0.4 0.4" />

    <!-- ============== ROBOT BODY ============== -->
    <!-- Pelvis is fixed (standing pose, no freejoint) -->
    <body name="pelvis" pos="0 0 0.793">
      <site name="imu" size="0.01" pos="0 0 0" />
      <inertial pos="0 0 -0.07605" quat="1 0 -0.000399148 0" mass="3.813"
        diaginertia="0.010549 0.0093089 0.0079184" />
      <!-- Visual geoms -->
      <geom type="mesh" class="visual" rgba="0.2 0.2 0.2 1" mesh="pelvis" />
      <geom type="mesh" class="visual" rgba="0.7 0.7 0.7 1" mesh="pelvis_contour_link" />
      <!-- Collision geom -->
      <geom type="mesh" class="collision_body" mesh="pelvis_contour_link" />

      <!-- ===== LEFT LEG (locked, visual only) ===== -->
      <body name="left_hip_pitch_link" pos="0 0.064452 -0.1027">
        <geom type="mesh" class="visual" rgba="0.2 0.2 0.2 1" mesh="left_hip_pitch_link" />
        <body name="left_hip_roll_link" pos="0 0.052 -0.030465" quat="0.996179 0 -0.0873386 0">
          <geom type="mesh" class="visual" rgba="0.7 0.7 0.7 1" mesh="left_hip_roll_link" />
          <body name="left_hip_yaw_link" pos="0.025001 0 -0.12412">
            <geom type="mesh" class="visual" rgba="0.7 0.7 0.7 1" mesh="left_hip_yaw_link" />
            <body name="left_knee_link" pos="-0.078273 0.0021489 -0.17734" quat="0.996179 0 0.0873386 0">
              <geom type="mesh" class="visual" rgba="0.7 0.7 0.7 1" mesh="left_knee_link" />
              <body name="left_ankle_pitch_link" pos="0 -9.4445e-05 -0.30001">
                <geom type="mesh" class="visual" rgba="0.7 0.7 0.7 1" mesh="left_ankle_pitch_link" />
                <body name="left_ankle_roll_link" pos="0 0 -0.017558">
                  <geom type="mesh" class="visual" rgba="0.2 0.2 0.2 1" mesh="left_ankle_roll_link" />
                  <geom size="0.005" pos="-0.05 0.025 -0.03" class="collision_body" />
                  <geom size="0.005" pos="-0.05 -0.025 -0.03" class="collision_body" />
                  <geom size="0.005" pos="0.12 0.03 -0.03" class="collision_body" />
                  <geom size="0.005" pos="0.12 -0.03 -0.03" class="collision_body" />
                </body>
              </body>
            </body>
          </body>
        </body>
      </body>

      <!-- ===== RIGHT LEG (locked, visual only) ===== -->
      <body name="right_hip_pitch_link" pos="0 -0.064452 -0.1027">
        <geom type="mesh" class="visual" rgba="0.2 0.2 0.2 1" mesh="right_hip_pitch_link" />
        <body name="right_hip_roll_link" pos="0 -0.052 -0.030465" quat="0.996179 0 -0.0873386 0">
          <geom type="mesh" class="visual" rgba="0.7 0.7 0.7 1" mesh="right_hip_roll_link" />
          <body name="right_hip_yaw_link" pos="0.025001 0 -0.12412">
            <geom type="mesh" class="visual" rgba="0.7 0.7 0.7 1" mesh="right_hip_yaw_link" />
            <body name="right_knee_link" pos="-0.078273 -0.0021489 -0.17734" quat="0.996179 0 0.0873386 0">
              <geom type="mesh" class="visual" rgba="0.7 0.7 0.7 1" mesh="right_knee_link" />
              <body name="right_ankle_pitch_link" pos="0 9.4445e-05 -0.30001">
                <geom type="mesh" class="visual" rgba="0.7 0.7 0.7 1" mesh="right_ankle_pitch_link" />
                <body name="right_ankle_roll_link" pos="0 0 -0.017558">
                  <geom type="mesh" class="visual" rgba="0.2 0.2 0.2 1" mesh="right_ankle_roll_link" />
                  <geom size="0.005" pos="-0.05 0.025 -0.03" class="collision_body" />
                  <geom size="0.005" pos="-0.05 -0.025 -0.03" class="collision_body" />
                  <geom size="0.005" pos="0.12 0.03 -0.03" class="collision_body" />
                  <geom size="0.005" pos="0.12 -0.03 -0.03" class="collision_body" />
                </body>
              </body>
            </body>
          </body>
        </body>
      </body>

      <!-- ===== TORSO (locked waist, visual + collision) ===== -->
      <body name="waist_yaw_link">
        <inertial pos="0.003964 0 0.018769" quat="-0.0178291 0.628464 0.0282471 0.777121"
          mass="0.244" diaginertia="0.000158561 0.000124229 9.67669e-05" />
        <geom type="mesh" class="visual" rgba="0.7 0.7 0.7 1" mesh="waist_yaw_link" />
        <body name="waist_roll_link" pos="-0.0039635 0 0.035">
          <inertial pos="0 -0.000236 0.010111" quat="0.99979 0.020492 0 0" mass="0.047"
            diaginertia="7.515e-06 6.40206e-06 3.98394e-06" />
          <geom type="mesh" class="visual" rgba="0.7 0.7 0.7 1" mesh="waist_roll_link" />
          <body name="torso_link" pos="0 0 0.019">
            <inertial pos="0.00331658 0.000261533 0.179856"
              quat="0.999831 0.000376204 0.0179895 -0.00377704" mass="9.598"
              diaginertia="0.12407 0.111951 0.0325382" />
            <!-- Visual geoms -->
            <geom type="mesh" class="visual" rgba="0.7 0.7 0.7 1" mesh="torso_link" />
            <geom pos="0.0039635 0 -0.054" type="mesh" class="visual" rgba="0.2 0.2 0.2 1" mesh="logo_link" />
            <geom pos="0.0039635 0 -0.054" type="mesh" class="visual" rgba="0.2 0.2 0.2 1" mesh="head_link" />
            <geom pos="0.0039635 0 -0.054" type="mesh" class="visual" rgba="0.7 0.7 0.7 1" mesh="waist_support_link" />
            <!-- Collision geom for torso -->
            <geom type="mesh" class="collision_body" mesh="torso_link" />

            <!-- ===== LEFT ARM ===== -->
            <body name="left_shoulder_pitch_link" pos="0.0039563 0.10022 0.23778"
              quat="0.990264 0.139201 1.38722e-05 -9.86868e-05">
              <inertial pos="0 0.035892 -0.011628" quat="0.654152 0.0130458 -0.326267 0.68225"
                mass="0.718" diaginertia="0.000465864 0.000432842 0.000406394" />
              <joint name="left_shoulder_pitch_joint" axis="0 1 0"
                range="-3.0892 2.6704" class="arm_motor" />
              <geom type="mesh" class="visual" rgba="0.7 0.7 0.7 1" mesh="left_shoulder_pitch_link" />
              <geom size="0.03 0.025" pos="0 0.04 -0.01" quat="0.707107 0 0.707107 0"
                type="cylinder" class="collision_arm" />

              <body name="left_shoulder_roll_link" pos="0 0.038 -0.013831"
                quat="0.990268 -0.139172 0 0">
                <inertial pos="-0.000227 0.00727 -0.063243"
                  quat="0.701256 -0.0196223 -0.00710317 0.712604" mass="0.643"
                  diaginertia="0.000691311 0.000618011 0.000388977" />
                <joint name="left_shoulder_roll_joint" axis="1 0 0"
                  range="-1.5882 2.2515" class="arm_motor" />
                <geom type="mesh" class="visual" rgba="0.7 0.7 0.7 1" mesh="left_shoulder_roll_link" />
                <geom size="0.03 0.015" pos="-0.004 0.006 -0.053" type="cylinder" class="collision_arm" />

                <body name="left_shoulder_yaw_link" pos="0 0.00624 -0.1032">
                  <inertial pos="0.010773 -0.002949 -0.072009"
                    quat="0.716879 -0.0964829 -0.0679942 0.687134" mass="0.734"
                    diaginertia="0.00106187 0.00103217 0.000400661" />
                  <joint name="left_shoulder_yaw_joint" axis="0 0 1"
                    range="-2.618 2.618" class="arm_motor" />
                  <geom type="mesh" class="visual" rgba="0.7 0.7 0.7 1" mesh="left_shoulder_yaw_link" />
                  <geom type="mesh" class="collision_arm" mesh="left_shoulder_yaw_link" />

                  <body name="left_elbow_link" pos="0.015783 0 -0.080518">
                    <inertial pos="0.064956 0.004454 -0.010062"
                      quat="0.541765 0.636132 0.388821 0.388129" mass="0.6"
                      diaginertia="0.000443035 0.000421612 0.000259353" />
                    <joint name="left_elbow_joint" axis="0 1 0"
                      range="-1.0472 2.0944" class="arm_motor" />
                    <geom type="mesh" class="visual" rgba="0.7 0.7 0.7 1" mesh="left_elbow_link" />
                    <geom type="mesh" class="collision_arm" mesh="left_elbow_link" />

                    <body name="left_wrist_roll_link" pos="0.1 0.00188791 -0.01">
                      <inertial pos="0.0171394 0.000537591 4.8864e-07"
                        quat="0.575338 0.411667 -0.574906 0.411094" mass="0.085445"
                        diaginertia="5.48211e-05 4.96646e-05 3.57798e-05" />
                      <joint name="left_wrist_roll_joint" axis="1 0 0"
                        range="-1.97222 1.97222" class="arm_motor" />
                      <geom type="mesh" class="visual" rgba="0.7 0.7 0.7 1" mesh="left_wrist_roll_link" />
                      <geom type="mesh" class="collision_arm" mesh="left_wrist_roll_link" />

                      <body name="left_wrist_pitch_link" pos="0.038 0 0">
                        <inertial pos="0.0229999 -0.00111685 -0.00111658"
                          quat="0.249998 0.661363 0.293036 0.643608" mass="0.48405"
                          diaginertia="0.000430353 0.000429873 0.000164648" />
                        <joint name="left_wrist_pitch_joint" axis="0 1 0"
                          range="-1.61443 1.61443" class="wrist_motor" />
                        <geom type="mesh" class="visual" rgba="0.7 0.7 0.7 1" mesh="left_wrist_pitch_link" />
                        <geom type="mesh" class="collision_arm" mesh="left_wrist_pitch_link" />

                        <body name="left_wrist_yaw_link" pos="0.046 0 0">
                          <inertial pos="0.0708244 0.000191745 0.00161742"
                            quat="0.510571 0.526295 0.468078 0.493188" mass="0.254576"
                            diaginertia="0.000646113 0.000559993 0.000147566" />
                          <joint name="left_wrist_yaw_joint" axis="0 0 1"
                            range="-1.61443 1.61443" class="wrist_motor" />
                          <geom type="mesh" class="visual" rgba="0.7 0.7 0.7 1" mesh="left_wrist_yaw_link" />
                          <geom type="mesh" class="collision_arm" mesh="left_wrist_yaw_link" />

                          <!-- LEFT DEX3 HAND attached at rubber_hand offset -->
                          <body name="left_hand_palm_link" pos="0.0415 0.003 0">
                            <inertial pos="0.06215 -0.00051 -0.00058" mass="0.373"
                              diaginertia="0.000540 0.000396 0.000275" />
                            <geom type="mesh" class="visual" rgba="0.7 0.7 0.7 1" mesh="left_hand_palm_link" />
                            <geom type="mesh" class="collision_hand" mesh="left_hand_palm_link" />

                            <!-- Thumb chain: 3 joints -->
                            <body name="left_hand_thumb_0_link" pos="0.0255 0 0">
                              <inertial pos="-0.00088 -0.00863 0.00094" mass="0.0862"
                                diaginertia="1.64e-05 1.60e-05 1.45e-05" />
                              <joint name="left_hand_thumb_0_joint" axis="0 1 0"
                                range="-1.0472 1.0472" class="hand_motor" />
                              <geom type="mesh" class="visual" rgba="0.7 0.7 0.7 1" mesh="left_hand_thumb_0_link" />
                              <geom type="mesh" class="collision_hand" mesh="left_hand_thumb_0_link" />

                              <body name="left_hand_thumb_1_link" pos="-0.0025 -0.0193 0">
                                <inertial pos="-0.00083 -0.03547 -0.00038" mass="0.0589"
                                  diaginertia="1.27e-05 1.23e-05 6.02e-06" />
                                <joint name="left_hand_thumb_1_joint" axis="0 0 1"
                                  range="-0.7243 0.920" class="hand_motor" />
                                <geom type="mesh" class="visual" rgba="0.7 0.7 0.7 1" mesh="left_hand_thumb_1_link" />
                                <geom type="box" size="0.01 0.015 0.01" pos="-0.001 -0.032 0" class="collision_hand" />

                                <body name="left_hand_thumb_2_link" pos="0 -0.0458 0">
                                  <inertial pos="-0.00172 -0.02628 0.00011" mass="0.0203"
                                    diaginertia="4.61e-06 3.87e-06 1.54e-06" />
                                  <joint name="left_hand_thumb_2_joint" axis="0 0 1"
                                    range="0 1.7453" class="hand_motor" />
                                  <geom type="mesh" class="visual" rgba="0.7 0.7 0.7 1" mesh="left_hand_thumb_2_link" />
                                  <geom type="mesh" class="collision_hand" mesh="left_hand_thumb_2_link" />
                                  <site name="left_thumb_tip" pos="0 -0.05 0" size="0.005" />
                                </body>
                              </body>
                            </body>

                            <!-- Middle finger: 2 joints -->
                            <body name="left_hand_middle_0_link" pos="0.0777 0.0016 -0.0285">
                              <inertial pos="0.03547 0.00083 0.00038" mass="0.0589"
                                diaginertia="1.27e-05 1.23e-05 6.02e-06" />
                              <joint name="left_hand_middle_0_joint" axis="0 0 1"
                                range="-1.5708 0" class="hand_motor" />
                              <geom type="mesh" class="visual" rgba="0.7 0.7 0.7 1" mesh="left_hand_middle_0_link" />
                              <geom type="mesh" class="collision_hand" mesh="left_hand_middle_0_link" />

                              <body name="left_hand_middle_1_link" pos="0.0458 0 0">
                                <inertial pos="0.02628 0.00172 -0.00011" mass="0.0203"
                                  diaginertia="4.61e-06 3.87e-06 1.54e-06" />
                                <joint name="left_hand_middle_1_joint" axis="0 0 1"
                                  range="-1.7453 0" class="hand_motor" />
                                <geom type="mesh" class="visual" rgba="0.7 0.7 0.7 1" mesh="left_hand_middle_1_link" />
                                <geom type="mesh" class="collision_hand" mesh="left_hand_middle_1_link" />
                                <site name="left_middle_tip" pos="0.05 0 0" size="0.005" />
                              </body>
                            </body>

                            <!-- Index finger: 2 joints -->
                            <body name="left_hand_index_0_link" pos="0.0777 0.0016 0.0285">
                              <inertial pos="0.03547 0.00083 0.00038" mass="0.0589"
                                diaginertia="1.27e-05 1.23e-05 6.02e-06" />
                              <joint name="left_hand_index_0_joint" axis="0 0 1"
                                range="-1.5708 0" class="hand_motor" />
                              <geom type="mesh" class="visual" rgba="0.7 0.7 0.7 1" mesh="left_hand_index_0_link" />
                              <geom type="mesh" class="collision_hand" mesh="left_hand_index_0_link" />

                              <body name="left_hand_index_1_link" pos="0.0458 0 0">
                                <inertial pos="0.02628 0.00172 -0.00011" mass="0.0203"
                                  diaginertia="4.61e-06 3.87e-06 1.54e-06" />
                                <joint name="left_hand_index_1_joint" axis="0 0 1"
                                  range="-1.7453 0" class="hand_motor" />
                                <geom type="mesh" class="visual" rgba="0.7 0.7 0.7 1" mesh="left_hand_index_1_link" />
                                <geom type="mesh" class="collision_hand" mesh="left_hand_index_1_link" />
                                <site name="left_index_tip" pos="0.05 0 0" size="0.005" />
                              </body>
                            </body>
                          </body> <!-- end left_hand_palm_link -->
                        </body> <!-- end left_wrist_yaw_link -->
                      </body>
                    </body>
                  </body>
                </body>
              </body>
            </body> <!-- end left_shoulder_pitch_link -->

            <!-- ===== RIGHT ARM ===== -->
            <body name="right_shoulder_pitch_link" pos="0.0039563 -0.10021 0.23778"
              quat="0.990264 -0.139201 1.38722e-05 9.86868e-05">
              <inertial pos="0 -0.035892 -0.011628" quat="0.68225 -0.326267 0.0130458 0.654152"
                mass="0.718" diaginertia="0.000465864 0.000432842 0.000406394" />
              <joint name="right_shoulder_pitch_joint" axis="0 1 0"
                range="-3.0892 2.6704" class="arm_motor" />
              <geom type="mesh" class="visual" rgba="0.7 0.7 0.7 1" mesh="right_shoulder_pitch_link" />
              <geom size="0.03 0.025" pos="0 -0.04 -0.01" quat="0.707107 0 0.707107 0"
                type="cylinder" class="collision_arm" />

              <body name="right_shoulder_roll_link" pos="0 -0.038 -0.013831"
                quat="0.990268 0.139172 0 0">
                <inertial pos="-0.000227 -0.00727 -0.063243"
                  quat="0.712604 -0.00710317 -0.0196223 0.701256" mass="0.643"
                  diaginertia="0.000691311 0.000618011 0.000388977" />
                <joint name="right_shoulder_roll_joint" axis="1 0 0"
                  range="-2.2515 1.5882" class="arm_motor" />
                <geom type="mesh" class="visual" rgba="0.7 0.7 0.7 1" mesh="right_shoulder_roll_link" />
                <geom size="0.03 0.015" pos="-0.004 -0.006 -0.053" type="cylinder" class="collision_arm" />

                <body name="right_shoulder_yaw_link" pos="0 -0.00624 -0.1032">
                  <inertial pos="0.010773 0.002949 -0.072009"
                    quat="0.687134 -0.0679942 -0.0964829 0.716879" mass="0.734"
                    diaginertia="0.00106187 0.00103217 0.000400661" />
                  <joint name="right_shoulder_yaw_joint" axis="0 0 1"
                    range="-2.618 2.618" class="arm_motor" />
                  <geom type="mesh" class="visual" rgba="0.7 0.7 0.7 1" mesh="right_shoulder_yaw_link" />
                  <geom type="mesh" class="collision_arm" mesh="right_shoulder_yaw_link" />

                  <body name="right_elbow_link" pos="0.015783 0 -0.080518">
                    <inertial pos="0.064956 -0.004454 -0.010062"
                      quat="0.388129 0.388821 0.636132 0.541765" mass="0.6"
                      diaginertia="0.000443035 0.000421612 0.000259353" />
                    <joint name="right_elbow_joint" axis="0 1 0"
                      range="-1.0472 2.0944" class="arm_motor" />
                    <geom type="mesh" class="visual" rgba="0.7 0.7 0.7 1" mesh="right_elbow_link" />
                    <geom type="mesh" class="collision_arm" mesh="right_elbow_link" />

                    <body name="right_wrist_roll_link" pos="0.1 -0.00188791 -0.01">
                      <inertial pos="0.0171394 -0.000537591 4.8864e-07"
                        quat="0.411667 0.575338 -0.411094 0.574906" mass="0.085445"
                        diaginertia="5.48211e-05 4.96646e-05 3.57798e-05" />
                      <joint name="right_wrist_roll_joint" axis="1 0 0"
                        range="-1.97222 1.97222" class="arm_motor" />
                      <geom type="mesh" class="visual" rgba="0.7 0.7 0.7 1" mesh="right_wrist_roll_link" />
                      <geom type="mesh" class="collision_arm" mesh="right_wrist_roll_link" />

                      <body name="right_wrist_pitch_link" pos="0.038 0 0">
                        <inertial pos="0.0229999 0.00111685 -0.00111658"
                          quat="0.643608 0.293036 0.661363 0.249998" mass="0.48405"
                          diaginertia="0.000430353 0.000429873 0.000164648" />
                        <joint name="right_wrist_pitch_joint" axis="0 1 0"
                          range="-1.61443 1.61443" class="wrist_motor" />
                        <geom type="mesh" class="visual" rgba="0.7 0.7 0.7 1" mesh="right_wrist_pitch_link" />
                        <geom type="mesh" class="collision_arm" mesh="right_wrist_pitch_link" />

                        <body name="right_wrist_yaw_link" pos="0.046 0 0">
                          <inertial pos="0.0708244 -0.000191745 0.00161742"
                            quat="0.493188 0.468078 0.526295 0.510571" mass="0.254576"
                            diaginertia="0.000646113 0.000559993 0.000147566" />
                          <joint name="right_wrist_yaw_joint" axis="0 0 1"
                            range="-1.61443 1.61443" class="wrist_motor" />
                          <geom type="mesh" class="visual" rgba="0.7 0.7 0.7 1" mesh="right_wrist_yaw_link" />
                          <geom type="mesh" class="collision_arm" mesh="right_wrist_yaw_link" />

                          <!-- RIGHT DEX3 HAND attached at rubber_hand offset -->
                          <body name="right_hand_palm_link" pos="0.0415 -0.003 0">
                            <inertial pos="0.06215 0.00051 -0.00058" mass="0.373"
                              diaginertia="0.000540 0.000396 0.000275" />
                            <geom type="mesh" class="visual" rgba="0.7 0.7 0.7 1" mesh="right_hand_palm_link" />
                            <geom type="mesh" class="collision_hand" mesh="right_hand_palm_link" />

                            <!-- Thumb chain: 3 joints -->
                            <body name="right_hand_thumb_0_link" pos="0.0255 0 0">
                              <inertial pos="-0.00088 0.00863 0.00094" mass="0.0862"
                                diaginertia="1.64e-05 1.60e-05 1.45e-05" />
                              <joint name="right_hand_thumb_0_joint" axis="0 1 0"
                                range="-1.0472 1.0472" class="hand_motor" />
                              <geom type="mesh" class="visual" rgba="0.7 0.7 0.7 1" mesh="right_hand_thumb_0_link" />
                              <geom type="mesh" class="collision_hand" mesh="right_hand_thumb_0_link" />

                              <body name="right_hand_thumb_1_link" pos="-0.0025 0.0193 0">
                                <inertial pos="-0.00083 0.03547 -0.00038" mass="0.0589"
                                  diaginertia="1.27e-05 1.23e-05 6.02e-06" />
                                <joint name="right_hand_thumb_1_joint" axis="0 0 1"
                                  range="-0.920 0.7243" class="hand_motor" />
                                <geom type="mesh" class="visual" rgba="0.7 0.7 0.7 1" mesh="right_hand_thumb_1_link" />
                                <geom type="box" size="0.01 0.015 0.01" pos="-0.001 0.032 0" class="collision_hand" />

                                <body name="right_hand_thumb_2_link" pos="0 0.0458 0">
                                  <inertial pos="-0.00172 0.02628 0.00011" mass="0.0203"
                                    diaginertia="4.61e-06 3.87e-06 1.54e-06" />
                                  <joint name="right_hand_thumb_2_joint" axis="0 0 1"
                                    range="-1.7453 0" class="hand_motor" />
                                  <geom type="mesh" class="visual" rgba="0.7 0.7 0.7 1" mesh="right_hand_thumb_2_link" />
                                  <geom type="mesh" class="collision_hand" mesh="right_hand_thumb_2_link" />
                                  <site name="right_thumb_tip" pos="0 0.05 0" size="0.005" />
                                </body>
                              </body>
                            </body>

                            <!-- Middle finger: 2 joints -->
                            <body name="right_hand_middle_0_link" pos="0.0777 -0.0016 -0.0285">
                              <inertial pos="0.03547 -0.00083 0.00038" mass="0.0589"
                                diaginertia="1.27e-05 1.23e-05 6.02e-06" />
                              <joint name="right_hand_middle_0_joint" axis="0 0 1"
                                range="0 1.5708" class="hand_motor" />
                              <geom type="mesh" class="visual" rgba="0.7 0.7 0.7 1" mesh="right_hand_middle_0_link" />
                              <geom type="mesh" class="collision_hand" mesh="right_hand_middle_0_link" />

                              <body name="right_hand_middle_1_link" pos="0.0458 0 0">
                                <inertial pos="0.02628 -0.00172 -0.00011" mass="0.0203"
                                  diaginertia="4.61e-06 3.87e-06 1.54e-06" />
                                <joint name="right_hand_middle_1_joint" axis="0 0 1"
                                  range="0 1.7453" class="hand_motor" />
                                <geom type="mesh" class="visual" rgba="0.7 0.7 0.7 1" mesh="right_hand_middle_1_link" />
                                <geom type="mesh" class="collision_hand" mesh="right_hand_middle_1_link" />
                                <site name="right_middle_tip" pos="0.05 0 0" size="0.005" />
                              </body>
                            </body>

                            <!-- Index finger: 2 joints -->
                            <body name="right_hand_index_0_link" pos="0.0777 -0.0016 0.0285">
                              <inertial pos="0.03547 -0.00083 0.00038" mass="0.0589"
                                diaginertia="1.27e-05 1.23e-05 6.02e-06" />
                              <joint name="right_hand_index_0_joint" axis="0 0 1"
                                range="0 1.5708" class="hand_motor" />
                              <geom type="mesh" class="visual" rgba="0.7 0.7 0.7 1" mesh="right_hand_index_0_link" />
                              <geom type="mesh" class="collision_hand" mesh="right_hand_index_0_link" />

                              <body name="right_hand_index_1_link" pos="0.0458 0 0">
                                <inertial pos="0.02628 -0.00172 -0.00011" mass="0.0203"
                                  diaginertia="4.61e-06 3.87e-06 1.54e-06" />
                                <joint name="right_hand_index_1_joint" axis="0 0 1"
                                  range="0 1.7453" class="hand_motor" />
                                <geom type="mesh" class="visual" rgba="0.7 0.7 0.7 1" mesh="right_hand_index_1_link" />
                                <geom type="mesh" class="collision_hand" mesh="right_hand_index_1_link" />
                                <site name="right_index_tip" pos="0.05 0 0" size="0.005" />
                              </body>
                            </body>
                          </body> <!-- end right_hand_palm_link -->
                        </body> <!-- end right_wrist_yaw_link -->
                      </body>
                    </body>
                  </body>
                </body>
              </body>
            </body> <!-- end right_shoulder_pitch_link -->
          </body> <!-- end torso_link -->
        </body> <!-- end waist_roll_link -->
      </body> <!-- end waist_yaw_link -->
    </body> <!-- end pelvis -->

    <!-- ============== TABLE ============== -->
    <body name="table" pos="0 0 0">
      <geom name="table_top" type="box" size="0.5 0.3 0.015" pos="0 0 0.78"
        material="table_wood" class="collision_object" mass="10" />
      <geom name="table_leg_1" type="box" size="0.02 0.02 0.39" pos="-0.46 -0.26 0.39"
        material="table_wood" class="collision_object" />
      <geom name="table_leg_2" type="box" size="0.02 0.02 0.39" pos="0.46 -0.26 0.39"
        material="table_wood" class="collision_object" />
      <geom name="table_leg_3" type="box" size="0.02 0.02 0.39" pos="-0.46 0.26 0.39"
        material="table_wood" class="collision_object" />
      <geom name="table_leg_4" type="box" size="0.02 0.02 0.39" pos="0.46 0.26 0.39"
        material="table_wood" class="collision_object" />
    </body>

    <!-- ============== MANIPULABLE OBJECTS ============== -->
    <body name="red_cube" pos="-0.15 0 0.82">
      <freejoint name="red_cube_joint" />
      <inertial pos="0 0 0" mass="0.05" diaginertia="2.08e-05 2.08e-05 2.08e-05" />
      <geom name="red_cube_geom" type="box" size="0.025 0.025 0.025"
        material="red_obj" class="collision_object" mass="0.05" />
    </body>

    <body name="blue_cube" pos="0.15 0 0.82">
      <freejoint name="blue_cube_joint" />
      <inertial pos="0 0 0" mass="0.05" diaginertia="2.08e-05 2.08e-05 2.08e-05" />
      <geom name="blue_cube_geom" type="box" size="0.025 0.025 0.025"
        material="blue_obj" class="collision_object" mass="0.05" />
    </body>

    <body name="green_cube" pos="0 -0.1 0.82">
      <freejoint name="green_cube_joint" />
      <inertial pos="0 0 0" mass="0.05" diaginertia="2.08e-05 2.08e-05 2.08e-05" />
      <geom name="green_cube_geom" type="box" size="0.025 0.025 0.025"
        material="green_obj" class="collision_object" mass="0.05" />
    </body>
  </worldbody>

  <!-- ============== ACTUATORS (position control) ============== -->
  <actuator>
    <!-- Left arm (7 joints) -->
    <position name="left_shoulder_pitch"  joint="left_shoulder_pitch_joint"  class="arm_motor" />
    <position name="left_shoulder_roll"   joint="left_shoulder_roll_joint"   class="arm_motor" />
    <position name="left_shoulder_yaw"    joint="left_shoulder_yaw_joint"    class="arm_motor" />
    <position name="left_elbow"           joint="left_elbow_joint"           class="arm_motor" />
    <position name="left_wrist_roll"      joint="left_wrist_roll_joint"      class="arm_motor" />
    <position name="left_wrist_pitch"     joint="left_wrist_pitch_joint"     class="wrist_motor" />
    <position name="left_wrist_yaw"       joint="left_wrist_yaw_joint"       class="wrist_motor" />
    <!-- Right arm (7 joints) -->
    <position name="right_shoulder_pitch" joint="right_shoulder_pitch_joint" class="arm_motor" />
    <position name="right_shoulder_roll"  joint="right_shoulder_roll_joint"  class="arm_motor" />
    <position name="right_shoulder_yaw"   joint="right_shoulder_yaw_joint"   class="arm_motor" />
    <position name="right_elbow"          joint="right_elbow_joint"          class="arm_motor" />
    <position name="right_wrist_roll"     joint="right_wrist_roll_joint"     class="arm_motor" />
    <position name="right_wrist_pitch"    joint="right_wrist_pitch_joint"    class="wrist_motor" />
    <position name="right_wrist_yaw"      joint="right_wrist_yaw_joint"      class="wrist_motor" />
    <!-- Left hand (7 joints) -->
    <position name="left_hand_thumb_0"    joint="left_hand_thumb_0_joint"    class="hand_motor" />
    <position name="left_hand_thumb_1"    joint="left_hand_thumb_1_joint"    class="hand_motor" />
    <position name="left_hand_thumb_2"    joint="left_hand_thumb_2_joint"    class="hand_motor" />
    <position name="left_hand_middle_0"   joint="left_hand_middle_0_joint"   class="hand_motor" />
    <position name="left_hand_middle_1"   joint="left_hand_middle_1_joint"   class="hand_motor" />
    <position name="left_hand_index_0"    joint="left_hand_index_0_joint"    class="hand_motor" />
    <position name="left_hand_index_1"    joint="left_hand_index_1_joint"    class="hand_motor" />
    <!-- Right hand (7 joints) -->
    <position name="right_hand_thumb_0"   joint="right_hand_thumb_0_joint"   class="hand_motor" />
    <position name="right_hand_thumb_1"   joint="right_hand_thumb_1_joint"   class="hand_motor" />
    <position name="right_hand_thumb_2"   joint="right_hand_thumb_2_joint"   class="hand_motor" />
    <position name="right_hand_middle_0"  joint="right_hand_middle_0_joint"  class="hand_motor" />
    <position name="right_hand_middle_1"  joint="right_hand_middle_1_joint"  class="hand_motor" />
    <position name="right_hand_index_0"   joint="right_hand_index_0_joint"   class="hand_motor" />
    <position name="right_hand_index_1"   joint="right_hand_index_1_joint"   class="hand_motor" />
  </actuator>

  <!-- ============== SENSORS ============== -->
  <sensor>
    <!-- Arm joint positions -->
    <jointpos name="left_shoulder_pitch_pos"  joint="left_shoulder_pitch_joint" />
    <jointpos name="left_shoulder_roll_pos"   joint="left_shoulder_roll_joint" />
    <jointpos name="left_shoulder_yaw_pos"    joint="left_shoulder_yaw_joint" />
    <jointpos name="left_elbow_pos"           joint="left_elbow_joint" />
    <jointpos name="left_wrist_roll_pos"      joint="left_wrist_roll_joint" />
    <jointpos name="left_wrist_pitch_pos"     joint="left_wrist_pitch_joint" />
    <jointpos name="left_wrist_yaw_pos"       joint="left_wrist_yaw_joint" />
    <jointpos name="right_shoulder_pitch_pos" joint="right_shoulder_pitch_joint" />
    <jointpos name="right_shoulder_roll_pos"  joint="right_shoulder_roll_joint" />
    <jointpos name="right_shoulder_yaw_pos"   joint="right_shoulder_yaw_joint" />
    <jointpos name="right_elbow_pos"          joint="right_elbow_joint" />
    <jointpos name="right_wrist_roll_pos"     joint="right_wrist_roll_joint" />
    <jointpos name="right_wrist_pitch_pos"    joint="right_wrist_pitch_joint" />
    <jointpos name="right_wrist_yaw_pos"      joint="right_wrist_yaw_joint" />
    <!-- Hand joint positions -->
    <jointpos name="left_hand_thumb_0_pos"    joint="left_hand_thumb_0_joint" />
    <jointpos name="left_hand_thumb_1_pos"    joint="left_hand_thumb_1_joint" />
    <jointpos name="left_hand_thumb_2_pos"    joint="left_hand_thumb_2_joint" />
    <jointpos name="left_hand_middle_0_pos"   joint="left_hand_middle_0_joint" />
    <jointpos name="left_hand_middle_1_pos"   joint="left_hand_middle_1_joint" />
    <jointpos name="left_hand_index_0_pos"    joint="left_hand_index_0_joint" />
    <jointpos name="left_hand_index_1_pos"    joint="left_hand_index_1_joint" />
    <jointpos name="right_hand_thumb_0_pos"   joint="right_hand_thumb_0_joint" />
    <jointpos name="right_hand_thumb_1_pos"   joint="right_hand_thumb_1_joint" />
    <jointpos name="right_hand_thumb_2_pos"   joint="right_hand_thumb_2_joint" />
    <jointpos name="right_hand_middle_0_pos"  joint="right_hand_middle_0_joint" />
    <jointpos name="right_hand_middle_1_pos"  joint="right_hand_middle_1_joint" />
    <jointpos name="right_hand_index_0_pos"   joint="right_hand_index_0_joint" />
    <jointpos name="right_hand_index_1_pos"   joint="right_hand_index_1_joint" />
    <!-- Fingertip touch sensors -->
    <touch name="left_thumb_touch"  site="left_thumb_tip" />
    <touch name="left_middle_touch" site="left_middle_tip" />
    <touch name="left_index_touch"  site="left_index_tip" />
    <touch name="right_thumb_touch"  site="right_thumb_tip" />
    <touch name="right_middle_touch" site="right_middle_tip" />
    <touch name="right_index_touch"  site="right_index_tip" />
  </sensor>
</mujoco>
